Workbook

Sheet Data_Entry
A1: Diffusion coefficient and density data-entry template
A2: Model | B2: System / condition | C2: Observable | D2: Reference value | E2: Trajectory 1 | F2: Trajectory 2 | G2: Trajectory 3 | H2: N filled | I2: Mean | J2: Std | K2: SEM | L2: Unit | M2: Notes
A3: Experiment | B3: 300 K, 1 atm / proton-defect water | C3: D_H₂O | D3: 0.23 | H3: =COUNT(E3:G3) -> 0 | I3: =IF(H3=0,"",AVERAGE(E3:G3)) | J3: =IF(H3<2,"",_xludf.STDEV.S(E3:G3)) | K3: =IF(H3<2,"",J3/SQRT(H3)) | L3: Å²/ps | M3: 原始三列顺序: H2O, OH, H3O; 此处为 H2O
A4: Experiment | B4: 300 K, 1 atm / proton-defect water | C4: D_H₃O | D4: 0.93 | H4: =COUNT(E4:G4) -> 0 | I4: =IF(H4=0,"",AVERAGE(E4:G4)) | J4: =IF(H4<2,"",_xludf.STDEV.S(E4:G4)) | K4: =IF(H4<2,"",J4/SQRT(H4)) | L4: Å²/ps | M4: 原始三列顺序: H2O, OH, H3O; 此处为 H3O
A5: Experiment | B5: 300 K, 1 atm / proton-defect water | C5: D_OH | D5: 0.56 | H5: =COUNT(E5:G5) -> 0 | I5: =IF(H5=0,"",AVERAGE(E5:G5)) | J5: =IF(H5<2,"",_xludf.STDEV.S(E5:G5)) | K5: =IF(H5<2,"",J5/SQRT(H5)) | L5: Å²/ps | M5: 原始三列顺序: H2O, OH, H3O; 此处为 OH
A6: EeFF | B6: 300 K, 1 atm / proton-defect water | C6: D_H₂O | D6: 0.23 | E6: 0.2592968 | F6: 0.2619258 | G6: 0.2615236 | H6: =COUNT(E6:G6) -> 3 | I6: =IF(H6=0,"",AVERAGE(E6:G6)) -> 0.2609154 | J6: =IF(H6<2,"",_xludf.STDEV.S(E6:G6)) -> #NAME? | K6: =IF(H6<2,"",J6/SQRT(H6)) -> #NAME? | L6: Å²/ps | M6: 原始三列顺序: H2O, OH, H3O; 此处为 H2O
A7: EeFF | B7: 300 K, 1 atm / proton-defect water | C7: D_H₃O | D7: 0.61 | E7: 1.1489792 | F7: 1.1970556 | G7: 0.93441378 | H7: =COUNT(E7:G7) -> 3 | I7: =IF(H7=0,"",AVERAGE(E7:G7)) -> 1.0934829 | J7: =IF(H7<2,"",_xludf.STDEV.S(E7:G7)) -> #NAME? | K7: =IF(H7<2,"",J7/SQRT(H7)) -> #NAME? | L7: Å²/ps | M7: 原始三列顺序: H2O, OH, H3O; 此处为 H3O
A8: EeFF | B8: 300 K, 1 atm / proton-defect water | C8: D_OH | D8: 0.31 | E8: 0.45429284 | F8: 0.40624724 | G8: 0.36294542 | H8: =COUNT(E8:G8) -> 3 | I8: =IF(H8=0,"",AVERAGE(E8:G8)) -> 0.4078285 | J8: =IF(H8<2,"",_xludf.STDEV.S(E8:G8)) -> #NAME? | K8: =IF(H8<2,"",J8/SQRT(H8)) -> #NAME? | L8: Å²/ps | M8: 原始三列顺序: H2O, OH, H3O; 此处为 OH
A9: Lewis | B9: 300 K, 1 atm / proton-defect water | C9: D_H₂O | D9: 0.11 | E9: 0.05914653 | F9: 0.05752597 | G9: 0.05833189 | H9: =COUNT(E9:G9) -> 3 | I9: =IF(H9=0,"",AVERAGE(E9:G9)) -> 0.058334797 | J9: =IF(H9<2,"",_xludf.STDEV.S(E9:G9)) -> #NAME? | K9: =IF(H9<2,"",J9/SQRT(H9)) -> #NAME? | L9: Å²/ps | M9: 原始三列顺序: H2O, OH, H3O; 此处为 H2O
A10: Lewis | B10: 300 K, 1 atm / proton-defect water | C10: D_H₃O | D10: 0.24 | E10: 0.13344372 | F10: 0.16702823 | G10: 0.13166021 | H10: =COUNT(E10:G10) -> 3 | I10: =IF(H10=0,"",AVERAGE(E10:G10)) -> 0.14404405 | J10: =IF(H10<2,"",_xludf.STDEV.S(E10:G10)) -> #NAME? | K10: =IF(H10<2,"",J10/SQRT(H10)) -> #NAME? | L10: Å²/ps | M10: 原始三列顺序: H2O, OH, H3O; 此处为 H3O
A11: Lewis | B11: 300 K, 1 atm / proton-defect water | C11: D_OH | D11: 0.15 | E11: 0.12450995 | F11: 0.11571757 | G11: 0.10648552 | H11: =COUNT(E11:G11) -> 3 | I11: =IF(H11=0,"",AVERAGE(E11:G11)) -> 0.11557101 | J11: =IF(H11<2,"",_xludf.STDEV.S(E11:G11)) -> #NAME? | K11: =IF(H11<2,"",J11/SQRT(H11)) -> #NAME? | L11: Å²/ps | M11: 原始三列顺序: H2O, OH, H3O; 此处为 OH
A12: Cheng-MLP | B12: 300 K, 1 atm / proton-defect water | C12: D_H₂O | D12: 0.03 | E12: 0.03406953 | F12: 0.03258427 | G12: 0.03419714 | H12: =COUNT(E12:G12) -> 3 | I12: =IF(H12=0,"",AVERAGE(E12:G12)) -> 0.03361698 | J12: =IF(H12<2,"",_xludf.STDEV.S(E12:G12)) -> #NAME? | K12: =IF(H12<2,"",J12/SQRT(H12)) -> #NAME? | L12: Å²/ps | M12: 原始三列顺序: H2O, OH, H3O; 此处为 H2O
A13: Cheng-MLP | B13: 300 K, 1 atm / proton-defect water | C13: D_H₃O | D13: 0.2 | E13: 0.2002651 | F13: 0.10795055 | G13: 0.10795055 | H13: =COUNT(E13:G13) -> 3 | I13: =IF(H13=0,"",AVERAGE(E13:G13)) -> 0.13872207 | J13: =IF(H13<2,"",_xludf.STDEV.S(E13:G13)) -> #NAME? | K13: =IF(H13<2,"",J13/SQRT(H13)) -> #NAME? | L13: Å²/ps | M13: 原始三列顺序: H2O, OH, H3O; 此处为 H3O
A14: Cheng-MLP | B14: 300 K, 1 atm / proton-defect water | C14: D_OH | D14: 0.7 | E14: 0.52624221 | F14: 0.54689284 | G14: 0.62414891 | H14: =COUNT(E14:G14) -> 3 | I14: =IF(H14=0,"",AVERAGE(E14:G14)) -> 0.56576132 | J14: =IF(H14<2,"",_xludf.STDEV.S(E14:G14)) -> #NAME? | K14: =IF(H14<2,"",J14/SQRT(H14)) -> #NAME? | L14: Å²/ps | M14: 原始三列顺序: H2O, OH, H3O; 此处为 OH
A15: DP-H2OPD | B15: 300 K, 1 atm / proton-defect water | C15: D_H₂O | D15: 0.07 | E15: 0.07836033 | F15: 0.07680391 | G15: 0.07669582 | H15: =COUNT(E15:G15) -> 3 | I15: =IF(H15=0,"",AVERAGE(E15:G15)) -> 0.077286687 | J15: =IF(H15<2,"",_xludf.STDEV.S(E15:G15)) -> #NAME? | K15: =IF(H15<2,"",J15/SQRT(H15)) -> #NAME? | L15: Å²/ps | M15: 原始三列顺序: H2O, OH, H3O; 此处为 H2O
A16: DP-H2OPD | B16: 300 K, 1 atm / proton-defect water | C16: D_H₃O | D16: 0.6 | E16: 0.59992167 | F16: 0.63873264 | G16: 0.67945622 | H16: =COUNT(E16:G16) -> 3 | I16: =IF(H16=0,"",AVERAGE(E16:G16)) -> 0.63937018 | J16: =IF(H16<2,"",_xludf.STDEV.S(E16:G16)) -> #NAME? | K16: =IF(H16<2,"",J16/SQRT(H16)) -> #NAME? | L16: Å²/ps | M16: 原始三列顺序: H2O, OH, H3O; 此处为 H3O
A17: DP-H2OPD | B17: 300 K, 1 atm / proton-defect water | C17: D_OH | D17: 1 | E17: 0.995294 | F17: 1.1925243 | G17: 1.0963153 | H17: =COUNT(E17:G17) -> 3 | I17: =IF(H17=0,"",AVERAGE(E17:G17)) -> 1.0947112 | J17: =IF(H17<2,"",_xludf.STDEV.S(E17:G17)) -> #NAME? | K17: =IF(H17<2,"",J17/SQRT(H17)) -> #NAME? | L17: Å²/ps | M17: 原始三列顺序: H2O, OH, H3O; 此处为 OH
... A23: ReaxFF | B23: 300 K, 1 atm / proton-defect water | C23: D_OH | D23: 0.98 | E23: 0.64255593 | F23: 0.73561066 | G23: 0.78517417 | H23: =COUNT(E23:G23) -> 3 | I23: =IF(H23=0,"",AVERAGE(E23:G23)) -> 0.72111359 | J23: =IF(H23<2,"",_xludf.STDEV.S(E23:G23)) -> #NAME? | K23: =IF(H23<2,"",J23/SQRT(H23)) -> #NAME? | L23: Å²/ps | M23: 原始三列顺序: H2O, OH, H3O; 此处为 OH
A24: MACE | B24: 300 K, 1 atm / proton-defect water | C24: D_H₂O | D24: 0.14 | E24: 0.14 | H24: =COUNT(E24:G24) -> 1 | I24: =IF(H24=0,"",AVERAGE(E24:G24)) -> 0.14 | J24: =IF(H24<2,"",_xludf.STDEV.S(E24:G24)) | K24: =IF(H24<2,"",J24/SQRT(H24)) | L24: Å²/ps | M24: 原始三列顺序: H2O, OH, H3O; 此处为 H2O
A25: MACE | B25: 300 K, 1 atm / proton-defect water | C25: D_H₃O | D25: 0.08 | E25: 0.077074089 | H25: =COUNT(E25:G25) -> 1 | I25: =IF(H25=0,"",AVERAGE(E25:G25)) -> 0.077074089 | J25: =IF(H25<2,"",_xludf.STDEV.S(E25:G25)) | K25: =IF(H25<2,"",J25/SQRT(H25)) | L25: Å²/ps | M25: 原始三列顺序: H2O, OH, H3O; 此处为 H3O
A26: MACE | B26: 300 K, 1 atm / proton-defect water | C26: D_OH | D26: 0.33 | E26: 0.33 | H26: =COUNT(E26:G26) -> 1 | I26: =IF(H26=0,"",AVERAGE(E26:G26)) -> 0.33 | J26: =IF(H26<2,"",_xludf.STDEV.S(E26:G26)) | K26: =IF(H26<2,"",J26/SQRT(H26)) | L26: Å²/ps | M26: 原始三列顺序: H2O, OH, H3O; 此处为 OH
A27: DP-H3O/OH | B27: 300 K, 1 atm / proton-defect water | C27: D_H₂O | D27: 0 | E27: 0.009156987 | F27: 0.01160543 | H27: =COUNT(E27:G27) -> 2 | I27: =IF(H27=0,"",AVERAGE(E27:G27)) -> 0.010381208 | J27: =IF(H27<2,"",_xludf.STDEV.S(E27:G27)) -> #NAME? | K27: =IF(H27<2,"",J27/SQRT(H27)) -> #NAME? | L27: Å²/ps | M27: 原始三列顺序: H2O, OH, H3O; 此处为 H2O
A28: DP-H3O/OH | B28: 300 K, 1 atm / proton-defect water | C28: D_H₃O | D28: 0.02 | E28: 0.017222853 | H28: =COUNT(E28:G28) -> 1 | I28: =IF(H28=0,"",AVERAGE(E28:G28)) -> 0.017222853 | J28: =IF(H28<2,"",_xludf.STDEV.S(E28:G28)) | K28: =IF(H28<2,"",J28/SQRT(H28)) | L28: Å²/ps | M28: 原始三列顺序: H2O, OH, H3O; 此处为 H3O
A29: DP-H3O/OH | B29: 300 K, 1 atm / proton-defect water | C29: D_OH | D29: 0.18 | E29: 0.18004714 | H29: =COUNT(E29:G29) -> 1 | I29: =IF(H29=0,"",AVERAGE(E29:G29)) -> 0.18004714 | J29: =IF(H29<2,"",_xludf.STDEV.S(E29:G29)) | K29: =IF(H29<2,"",J29/SQRT(H29)) | L29: Å²/ps | M29: 原始三列顺序: H2O, OH, H3O; 此处为 OH
A30: AIMD | B30: 1020 K, 11 GPa | C30: D_O | D30: 0.9 | E30: 0.9 | H30: =COUNT(E30:G30) -> 1 | I30: =IF(H30=0,"",AVERAGE(E30:G30)) -> 0.9 | J30: =IF(H30<2,"",_xludf.STDEV.S(E30:G30)) | K30: =IF(H30<2,"",J30/SQRT(H30)) | L30: Å²/ps | M30: 高温高压体系氧扩散系数
A31: AIMD | B31: 1020 K, 11 GPa | C31: D_H | D31: 0.9 | E31: 0.9 | H31: =COUNT(E31:G31) -> 1 | I31: =IF(H31=0,"",AVERAGE(E31:G31)) -> 0.9 | J31: =IF(H31<2,"",_xludf.STDEV.S(E31:G31)) | K31: =IF(H31<2,"",J31/SQRT(H31)) | L31: Å²/ps | M31: 高温高压体系氢扩散系数
A32: AIMD | B32: 1020 K, 11 GPa | C32: rho | D32: 1.57 | E32: 1.57 | H32: =COUNT(E32:G32) -> 1 | I32: =IF(H32=0,"",AVERAGE(E32:G32)) -> 1.57 | J32: =IF(H32<2,"",_xludf.STDEV.S(E32:G32)) | K32: =IF(H32<2,"",J32/SQRT(H32)) | L32: g/cm³ | M32: 体系密度; ANI-1xnr 使用 NVT/AIMD 密度
A33: EeFF | B33: 1020 K, 11 GPa | C33: D_O | D33: 0.8 | E33: 0.89178453 | F33: 0.85641091 | G33: 0.89102726 | H33: =COUNT(E33:G33) -> 3 | I33: =IF(H33=0,"",AVERAGE(E33:G33)) -> 0.8797409 | J33: =IF(H33<2,"",_xludf.STDEV.S(E33:G33)) -> #NAME? | K33: =IF(H33<2,"",J33/SQRT(H33)) -> #NAME? | L33: Å²/ps | M33: 高温高压体系氧扩散系数
A34: EeFF | B34: 1020 K, 11 GPa | C34: D_H | D34: 0.82 | E34: 0.92982226 | F34: 0.90127505 | G34: 0.95058978 | H34: =COUNT(E34:G34) -> 3 | I34: =IF(H34=0,"",AVERAGE(E34:G34)) -> 0.92722903 | J34: =IF(H34<2,"",_xludf.STDEV.S(E34:G34)) -> #NAME? | K34: =IF(H34<2,"",J34/SQRT(H34)) -> #NAME? | L34: Å²/ps | M34: 高温高压体系氢扩散系数
A35: EeFF | B35: 1020 K, 11 GPa | C35: rho | D35: 1.69 | E35: 1.6765677 | F35: 1.6790214 | G35: 1.6773797 | H35: =COUNT(E35:G35) -> 3 | I35: =IF(H35=0,"",AVERAGE(E35:G35)) -> 1.6776563 | J35: =IF(H35<2,"",_xludf.STDEV.S(E35:G35)) -> #NAME? | K35: =IF(H35<2,"",J35/SQRT(H35)) -> #NAME? | L35: g/cm³ | M35: 体系密度; ANI-1xnr 使用 NVT/AIMD 密度
A36: Cheng-MLP | B36: 1020 K, 11 GPa | C36: D_O | D36: 0.73 | E36: 0.7343199 | F36: 0.7034786 | G36: 0.72361407 | H36: =COUNT(E36:G36) -> 3 | I36: =IF(H36=0,"",AVERAGE(E36:G36)) -> 0.72047086 | J36: =IF(H36<2,"",_xludf.STDEV.S(E36:G36)) -> #NAME? | K36: =IF(H36<2,"",J36/SQRT(H36)) -> #NAME? | L36: Å²/ps | M36: 高温高压体系氧扩散系数
A37: Cheng-MLP | B37: 1020 K, 11 GPa | C37: D_H | D37: 0.78 | E37: 0.79225433 | F37: 0.76719595 | G37: 0.77485989 | H37: =COUNT(E37:G37) -> 3 | I37: =IF(H37=0,"",AVERAGE(E37:G37)) -> 0.77810339 | J37: =IF(H37<2,"",_xludf.STDEV.S(E37:G37)) -> #NAME? | K37: =IF(H37<2,"",J37/SQRT(H37)) -> #NAME? | L37: Å²/ps | M37: 高温高压体系氢扩散系数
A38: Cheng-MLP | B38: 1020 K, 11 GPa | C38: rho | D38: 1.61 | E38: 1.6081778 | F38: 1.6088305 | G38: 1.6077531 | H38: =COUNT(E38:G38) -> 3 | I38: =IF(H38=0,"",AVERAGE(E38:G38)) -> 1.6082538 | J38: =IF(H38<2,"",_xludf.STDEV.S(E38:G38)) -> #NAME? | K38: =IF(H38<2,"",J38/SQRT(H38)) -> #NAME? | L38: g/cm³ | M38: 体系密度; ANI-1xnr 使用 NVT/AIMD 密度
A39: DP-H2OPD | B39: 1020 K, 11 GPa | C39: D_O | D39: 0.69 | E39: 0.67472439 | F39: 0.69677532 | G39: 0.6971099 | H39: =COUNT(E39:G39) -> 3 | I39: =IF(H39=0,"",AVERAGE(E39:G39)) -> 0.68953654 | J39: =IF(H39<2,"",_xludf.STDEV.S(E39:G39)) -> #NAME? | K39: =IF(H39<2,"",J39/SQRT(H39)) -> #NAME? | L39: Å²/ps | M39: 高温高压体系氧扩散系数
A40: DP-H2OPD | B40: 1020 K, 11 GPa | C40: D_H | D40: 0.72 | E40: 0.70866782 | F40: 0.71971659 | G40: 0.72633707 | H40: =COUNT(E40:G40) -> 3 | I40: =IF(H40=0,"",AVERAGE(E40:G40)) -> 0.71824049 | J40: =IF(H40<2,"",_xludf.STDEV.S(E40:G40)) -> #NAME? | K40: =IF(H40<2,"",J40/SQRT(H40)) -> #NAME? | L40: Å²/ps | M40: 高温高压体系氢扩散系数
A41: DP-H2OPD | B41: 1020 K, 11 GPa | C41: rho | D41: 1.66 | E41: 1.6621948 | F41: 1.6620611 | G41: 1.6619631 | H41: =COUNT(E41:G41) -> 3 | I41: =IF(H41=0,"",AVERAGE(E41:G41)) -> 1.662073 | J41: =IF(H41<2,"",_xludf.STDEV.S(E41:G41)) -> #NAME? | K41: =IF(H41<2,"",J41/SQRT(H41)) -> #NAME? | L41: g/cm³ | M41: 体系密度; ANI-1xnr 使用 NVT/AIMD 密度
A42: ANI-1xnr | B42: 1020 K, 11 GPa | C42: D_O | D42: 0.74 | E42: 0.80259595 | F42: 0.78953314 | G42: 0.77876549 | H42: =COUNT(E42:G42) -> 3 | I42: =IF(H42=0,"",AVERAGE(E42:G42)) -> 0.79029819 | J42: =IF(H42<2,"",_xludf.STDEV.S(E42:G42)) -> #NAME? | K42: =IF(H42<2,"",J42/SQRT(H42)) -> #NAME? | L42: Å²/ps | M42: 高温高压体系氧扩散系数
A43: ANI-1xnr | B43: 1020 K, 11 GPa | C43: D_H | D43: 0.8 | E43: 0.80259595 | F43: 0.78953314 | G43: 0.77876549 | H43: =COUNT(E43:G43) -> 3 | I43: =IF(H43=0,"",AVERAGE(E43:G43)) -> 0.79029819 | J43: =IF(H43<2,"",_xludf.STDEV.S(E43:G43)) -> #NAME? | K43: =IF(H43<2,"",J43/SQRT(H43)) -> #NAME? | L43: Å²/ps | M43: 高温高压体系氢扩散系数
A44: ANI-1xnr | B44: 1020 K, 11 GPa | C44: rho | D44: 1.57 | E44: 1.57 | F44: 1.57 | G44: 1.57 | H44: =COUNT(E44:G44) -> 3 | I44: =IF(H44=0,"",AVERAGE(E44:G44)) -> 1.57 | J44: =IF(H44<2,"",_xludf.STDEV.S(E44:G44)) -> #NAME? | K44: =IF(H44<2,"",J44/SQRT(H44)) -> #NAME? | L44: g/cm³ | M44: 体系密度; ANI-1xnr 使用 NVT/AIMD 密度
... A50: Lewis | B50: 1020 K, 11 GPa | C50: rho | D50: 1.66 | E50: 1.5780802 | F50: 1.5780802 | G50: 1.5786365 | H50: =COUNT(E50:G50) -> 3 | I50: =IF(H50=0,"",AVERAGE(E50:G50)) -> 1.5782656 | J50: =IF(H50<2,"",_xludf.STDEV.S(E50:G50)) -> #NAME? | K50: =IF(H50<2,"",J50/SQRT(H50)) -> #NAME? | L50: g/cm³ | M50: 体系密度; ANI-1xnr 使用 NVT/AIMD 密度
...

Sheet Plot_Summary
A1: Summary for plotting error bars
A2: Model | B2: System / condition | C2: Observable | D2: Plot value (Mean) | E2: Error bar (SEM) | F2: Std | G2: N | H2: Unit | I2: Reference value
A3: =Data_Entry!A3 -> Experiment | B3: =Data_Entry!B3 -> 300 K, 1 atm / proton-defect water | C3: =Data_Entry!C3 -> D_H₂O | D3: =Data_Entry!I3 | E3: =Data_Entry!K3 | F3: =Data_Entry!J3 | G3: =Data_Entry!H3 -> 0 | H3: =Data_Entry!L3 -> Å²/ps | I3: =Data_Entry!D3 -> 0.23
A4: =Data_Entry!A4 -> Experiment | B4: =Data_Entry!B4 -> 300 K, 1 atm / proton-defect water | C4: =Data_Entry!C4 -> D_H₃O | D4: =Data_Entry!I4 | E4: =Data_Entry!K4 | F4: =Data_Entry!J4 | G4: =Data_Entry!H4 -> 0 | H4: =Data_Entry!L4 -> Å²/ps | I4: =Data_Entry!D4 -> 0.93
A5: =Data_Entry!A5 -> Experiment | B5: =Data_Entry!B5 -> 300 K, 1 atm / proton-defect water | C5: =Data_Entry!C5 -> D_OH | D5: =Data_Entry!I5 | E5: =Data_Entry!K5 | F5: =Data_Entry!J5 | G5: =Data_Entry!H5 -> 0 | H5: =Data_Entry!L5 -> Å²/ps | I5: =Data_Entry!D5 -> 0.56
A6: =Data_Entry!A6 -> EeFF | B6: =Data_Entry!B6 -> 300 K, 1 atm / proton-defect water | C6: =Data_Entry!C6 -> D_H₂O | D6: =Data_Entry!I6 -> 0.2609154 | E6: =Data_Entry!K6 -> #NAME? | F6: =Data_Entry!J6 -> #NAME? | G6: =Data_Entry!H6 -> 3 | H6: =Data_Entry!L6 -> Å²/ps | I6: =Data_Entry!D6 -> 0.23
A7: =Data_Entry!A7 -> EeFF | B7: =Data_Entry!B7 -> 300 K, 1 atm / proton-defect water | C7: =Data_Entry!C7 -> D_H₃O | D7: =Data_Entry!I7 -> 1.0934829 | E7: =Data_Entry!K7 -> #NAME? | F7: =Data_Entry!J7 -> #NAME? | G7: =Data_Entry!H7 -> 3 | H7: =Data_Entry!L7 -> Å²/ps | I7: =Data_Entry!D7 -> 0.61
A8: =Data_Entry!A8 -> EeFF | B8: =Data_Entry!B8 -> 300 K, 1 atm / proton-defect water | C8: =Data_Entry!C8 -> D_OH | D8: =Data_Entry!I8 -> 0.4078285 | E8: =Data_Entry!K8 -> #NAME? | F8: =Data_Entry!J8 -> #NAME? | G8: =Data_Entry!H8 -> 3 | H8: =Data_Entry!L8 -> Å²/ps | I8: =Data_Entry!D8 -> 0.31
A9: =Data_Entry!A9 -> Lewis | B9: =Data_Entry!B9 -> 300 K, 1 atm / proton-defect water | C9: =Data_Entry!C9 -> D_H₂O | D9: =Data_Entry!I9 -> 0.058334797 | E9: =Data_Entry!K9 -> #NAME? | F9: =Data_Entry!J9 -> #NAME? | G9: =Data_Entry!H9 -> 3 | H9: =Data_Entry!L9 -> Å²/ps | I9: =Data_Entry!D9 -> 0.11
A10: =Data_Entry!A10 -> Lewis | B10: =Data_Entry!B10 -> 300 K, 1 atm / proton-defect water | C10: =Data_Entry!C10 -> D_H₃O | D10: =Data_Entry!I10 -> 0.14404405 | E10: =Data_Entry!K10 -> #NAME? | F10: =Data_Entry!J10 -> #NAME? | G10: =Data_Entry!H10 -> 3 | H10: =Data_Entry!L10 -> Å²/ps | I10: =Data_Entry!D10 -> 0.24
A11: =Data_Entry!A11 -> Lewis | B11: =Data_Entry!B11 -> 300 K, 1 atm / proton-defect water | C11: =Data_Entry!C11 -> D_OH | D11: =Data_Entry!I11 -> 0.11557101 | E11: =Data_Entry!K11 -> #NAME? | F11: =Data_Entry!J11 -> #NAME? | G11: =Data_Entry!H11 -> 3 | H11: =Data_Entry!L11 -> Å²/ps | I11: =Data_Entry!D11 -> 0.15
A12: =Data_Entry!A12 -> Cheng-MLP | B12: =Data_Entry!B12 -> 300 K, 1 atm / proton-defect water | C12: =Data_Entry!C12 -> D_H₂O | D12: =Data_Entry!I12 -> 0.03361698 | E12: =Data_Entry!K12 -> #NAME? | F12: =Data_Entry!J12 -> #NAME? | G12: =Data_Entry!H12 -> 3 | H12: =Data_Entry!L12 -> Å²/ps | I12: =Data_Entry!D12 -> 0.03
A13: =Data_Entry!A13 -> Cheng-MLP | B13: =Data_Entry!B13 -> 300 K, 1 atm / proton-defect water | C13: =Data_Entry!C13 -> D_H₃O | D13: =Data_Entry!I13 -> 0.13872207 | E13: =Data_Entry!K13 -> #NAME? | F13: =Data_Entry!J13 -> #NAME? | G13: =Data_Entry!H13 -> 3 | H13: =Data_Entry!L13 -> Å²/ps | I13: =Data_Entry!D13 -> 0.2
A14: =Data_Entry!A14 -> Cheng-MLP | B14: =Data_Entry!B14 -> 300 K, 1 atm / proton-defect water | C14: =Data_Entry!C14 -> D_OH | D14: =Data_Entry!I14 -> 0.56576132 | E14: =Data_Entry!K14 -> #NAME? | F14: =Data_Entry!J14 -> #NAME? | G14: =Data_Entry!H14 -> 3 | H14: =Data_Entry!L14 -> Å²/ps | I14: =Data_Entry!D14 -> 0.7
... A71: =Data_Entry!A71 -> Lewis | B71: =Data_Entry!B71 -> 1020 K, 20 GPa | C71: =Data_Entry!C71 -> rho | D71: =Data_Entry!I71 -> 1.83189 | E71: =Data_Entry!K71 -> #NAME? | F71: =Data_Entry!J71 -> #NAME? | G71: =Data_Entry!H71 -> 3 | H71: =Data_Entry!L71 -> g/cm³ | I71: =Data_Entry!D71 -> 1.66

Sheet Notes
A1: 说明 | B1: 内容
A2: 填写方式 | B2: 黄色列 Trajectory 1-3 用于填写三条独立轨迹的结果。Mean, Std, SEM 会自动计算。
A3: Ambient 数据顺序 | B3: 原始 D_H2O_OH_H3O 文件的三个数按 H2O, OH, H3O 读取；本表按 H2O, H3O, OH 展开。
A4: 高温高压新增体系 | B4: 已加入 1020 K, 11 GPa 和 1020 K, 20 GPa；每个体系包含 D_O, D_H 和 rho 三个指标。
A5: 模型命名 | B5: 原始文件中的 NNP 在本表统一写作 Cheng-MLP；DP_H2OPD 写作 DP-H2OPD；DP_H3O_OH 写作 DP-H3O/OH。
A6: 单位 | B6: 扩散系数单位为 Å²/ps；密度 rho 单位为 g/cm³。
A7: ANI-1xnr 注释 | B7: 高温高压数据源中注明 ANI-1xnr 采用 NVT，因为不能控压；表中保留在 Notes 列。
A8: 后续作图 | B8: 可直接使用 Plot_Summary 表中的 Plot value (Mean) 和 Error bar (SEM) 画误差棒。
